[2022-11-24 11:56:01,057] {processor.py:153} INFO - Started process (PID=45) to work on /opt/airflow/dags/second_dag.py
[2022-11-24 11:56:01,060] {processor.py:641} INFO - Processing file /opt/airflow/dags/second_dag.py for tasks to queue
[2022-11-24 11:56:01,064] {logging_mixin.py:115} INFO - [2022-11-24 11:56:01,064] {dagbag.py:507} INFO - Filling up the DagBag from /opt/airflow/dags/second_dag.py
[2022-11-24 11:56:01,677] {logging_mixin.py:115} INFO - [2022-11-24 11:56:01,656] {dagbag.py:320} ERROR - Failed to import: /opt/airflow/dags/second_dag.py
Traceback (most recent call last):
  File "/home/airflow/.local/lib/python3.7/site-packages/airflow/models/dagbag.py", line 317, in parse
    loader.exec_module(new_module)
  File "<frozen importlib._bootstrap_external>", line 728, in exec_module
  File "<frozen importlib._bootstrap>", line 219, in _call_with_frames_removed
  File "/opt/airflow/dags/second_dag.py", line 24, in <module>
    sshHook = SSHHook('ec2_ssh_connection')
  File "/home/airflow/.local/lib/python3.7/site-packages/airflow/providers/ssh/hooks/ssh.py", line 142, in __init__
    conn = self.get_connection(self.ssh_conn_id)
  File "/home/airflow/.local/lib/python3.7/site-packages/airflow/hooks/base.py", line 67, in get_connection
    conn = Connection.get_connection_from_secrets(conn_id)
  File "/home/airflow/.local/lib/python3.7/site-packages/airflow/models/connection.py", line 430, in get_connection_from_secrets
    raise AirflowNotFoundException(f"The conn_id `{conn_id}` isn't defined")
airflow.exceptions.AirflowNotFoundException: The conn_id `ec2_ssh_connection` isn't defined
[2022-11-24 11:56:01,686] {processor.py:653} WARNING - No viable dags retrieved from /opt/airflow/dags/second_dag.py
[2022-11-24 11:56:01,989] {processor.py:161} INFO - Processing /opt/airflow/dags/second_dag.py took 0.981 seconds
[2022-11-24 11:56:34,412] {processor.py:153} INFO - Started process (PID=110) to work on /opt/airflow/dags/second_dag.py
[2022-11-24 11:56:34,413] {processor.py:641} INFO - Processing file /opt/airflow/dags/second_dag.py for tasks to queue
[2022-11-24 11:56:34,414] {logging_mixin.py:115} INFO - [2022-11-24 11:56:34,414] {dagbag.py:507} INFO - Filling up the DagBag from /opt/airflow/dags/second_dag.py
[2022-11-24 11:56:34,482] {logging_mixin.py:115} INFO - [2022-11-24 11:56:34,478] {dagbag.py:320} ERROR - Failed to import: /opt/airflow/dags/second_dag.py
Traceback (most recent call last):
  File "/home/airflow/.local/lib/python3.7/site-packages/airflow/models/dagbag.py", line 317, in parse
    loader.exec_module(new_module)
  File "<frozen importlib._bootstrap_external>", line 728, in exec_module
  File "<frozen importlib._bootstrap>", line 219, in _call_with_frames_removed
  File "/opt/airflow/dags/second_dag.py", line 24, in <module>
    sshHook = SSHHook('ec2_ssh_connection')
  File "/home/airflow/.local/lib/python3.7/site-packages/airflow/providers/ssh/hooks/ssh.py", line 142, in __init__
    conn = self.get_connection(self.ssh_conn_id)
  File "/home/airflow/.local/lib/python3.7/site-packages/airflow/hooks/base.py", line 67, in get_connection
    conn = Connection.get_connection_from_secrets(conn_id)
  File "/home/airflow/.local/lib/python3.7/site-packages/airflow/models/connection.py", line 430, in get_connection_from_secrets
    raise AirflowNotFoundException(f"The conn_id `{conn_id}` isn't defined")
airflow.exceptions.AirflowNotFoundException: The conn_id `ec2_ssh_connection` isn't defined
[2022-11-24 11:56:34,483] {processor.py:653} WARNING - No viable dags retrieved from /opt/airflow/dags/second_dag.py
[2022-11-24 11:56:34,495] {processor.py:161} INFO - Processing /opt/airflow/dags/second_dag.py took 0.086 seconds
[2022-11-24 11:57:05,382] {processor.py:153} INFO - Started process (PID=164) to work on /opt/airflow/dags/second_dag.py
[2022-11-24 11:57:05,386] {processor.py:641} INFO - Processing file /opt/airflow/dags/second_dag.py for tasks to queue
[2022-11-24 11:57:05,387] {logging_mixin.py:115} INFO - [2022-11-24 11:57:05,387] {dagbag.py:507} INFO - Filling up the DagBag from /opt/airflow/dags/second_dag.py
[2022-11-24 11:57:05,447] {logging_mixin.py:115} INFO - [2022-11-24 11:57:05,444] {dagbag.py:320} ERROR - Failed to import: /opt/airflow/dags/second_dag.py
Traceback (most recent call last):
  File "/home/airflow/.local/lib/python3.7/site-packages/airflow/models/dagbag.py", line 317, in parse
    loader.exec_module(new_module)
  File "<frozen importlib._bootstrap_external>", line 728, in exec_module
  File "<frozen importlib._bootstrap>", line 219, in _call_with_frames_removed
  File "/opt/airflow/dags/second_dag.py", line 24, in <module>
    sshHook = SSHHook('ec2_ssh_connection')
  File "/home/airflow/.local/lib/python3.7/site-packages/airflow/providers/ssh/hooks/ssh.py", line 142, in __init__
    conn = self.get_connection(self.ssh_conn_id)
  File "/home/airflow/.local/lib/python3.7/site-packages/airflow/hooks/base.py", line 67, in get_connection
    conn = Connection.get_connection_from_secrets(conn_id)
  File "/home/airflow/.local/lib/python3.7/site-packages/airflow/models/connection.py", line 430, in get_connection_from_secrets
    raise AirflowNotFoundException(f"The conn_id `{conn_id}` isn't defined")
airflow.exceptions.AirflowNotFoundException: The conn_id `ec2_ssh_connection` isn't defined
[2022-11-24 11:57:05,449] {processor.py:653} WARNING - No viable dags retrieved from /opt/airflow/dags/second_dag.py
[2022-11-24 11:57:05,457] {processor.py:161} INFO - Processing /opt/airflow/dags/second_dag.py took 0.079 seconds
[2022-11-24 11:57:35,783] {processor.py:153} INFO - Started process (PID=228) to work on /opt/airflow/dags/second_dag.py
[2022-11-24 11:57:35,786] {processor.py:641} INFO - Processing file /opt/airflow/dags/second_dag.py for tasks to queue
[2022-11-24 11:57:35,789] {logging_mixin.py:115} INFO - [2022-11-24 11:57:35,789] {dagbag.py:507} INFO - Filling up the DagBag from /opt/airflow/dags/second_dag.py
[2022-11-24 11:57:35,883] {logging_mixin.py:115} INFO - [2022-11-24 11:57:35,868] {dagbag.py:320} ERROR - Failed to import: /opt/airflow/dags/second_dag.py
Traceback (most recent call last):
  File "/home/airflow/.local/lib/python3.7/site-packages/airflow/models/dagbag.py", line 317, in parse
    loader.exec_module(new_module)
  File "<frozen importlib._bootstrap_external>", line 728, in exec_module
  File "<frozen importlib._bootstrap>", line 219, in _call_with_frames_removed
  File "/opt/airflow/dags/second_dag.py", line 24, in <module>
    sshHook = SSHHook('ec2_ssh_connection')
  File "/home/airflow/.local/lib/python3.7/site-packages/airflow/providers/ssh/hooks/ssh.py", line 142, in __init__
    conn = self.get_connection(self.ssh_conn_id)
  File "/home/airflow/.local/lib/python3.7/site-packages/airflow/hooks/base.py", line 67, in get_connection
    conn = Connection.get_connection_from_secrets(conn_id)
  File "/home/airflow/.local/lib/python3.7/site-packages/airflow/models/connection.py", line 430, in get_connection_from_secrets
    raise AirflowNotFoundException(f"The conn_id `{conn_id}` isn't defined")
airflow.exceptions.AirflowNotFoundException: The conn_id `ec2_ssh_connection` isn't defined
[2022-11-24 11:57:35,884] {processor.py:653} WARNING - No viable dags retrieved from /opt/airflow/dags/second_dag.py
[2022-11-24 11:57:35,899] {processor.py:161} INFO - Processing /opt/airflow/dags/second_dag.py took 0.124 seconds
[2022-11-24 11:58:06,098] {processor.py:153} INFO - Started process (PID=295) to work on /opt/airflow/dags/second_dag.py
[2022-11-24 11:58:06,101] {processor.py:641} INFO - Processing file /opt/airflow/dags/second_dag.py for tasks to queue
[2022-11-24 11:58:06,103] {logging_mixin.py:115} INFO - [2022-11-24 11:58:06,103] {dagbag.py:507} INFO - Filling up the DagBag from /opt/airflow/dags/second_dag.py
[2022-11-24 11:58:06,157] {logging_mixin.py:115} INFO - [2022-11-24 11:58:06,155] {dagbag.py:320} ERROR - Failed to import: /opt/airflow/dags/second_dag.py
Traceback (most recent call last):
  File "/home/airflow/.local/lib/python3.7/site-packages/airflow/models/dagbag.py", line 317, in parse
    loader.exec_module(new_module)
  File "<frozen importlib._bootstrap_external>", line 728, in exec_module
  File "<frozen importlib._bootstrap>", line 219, in _call_with_frames_removed
  File "/opt/airflow/dags/second_dag.py", line 24, in <module>
    sshHook = SSHHook('ec2_ssh_connection')
  File "/home/airflow/.local/lib/python3.7/site-packages/airflow/providers/ssh/hooks/ssh.py", line 142, in __init__
    conn = self.get_connection(self.ssh_conn_id)
  File "/home/airflow/.local/lib/python3.7/site-packages/airflow/hooks/base.py", line 67, in get_connection
    conn = Connection.get_connection_from_secrets(conn_id)
  File "/home/airflow/.local/lib/python3.7/site-packages/airflow/models/connection.py", line 430, in get_connection_from_secrets
    raise AirflowNotFoundException(f"The conn_id `{conn_id}` isn't defined")
airflow.exceptions.AirflowNotFoundException: The conn_id `ec2_ssh_connection` isn't defined
[2022-11-24 11:58:06,158] {processor.py:653} WARNING - No viable dags retrieved from /opt/airflow/dags/second_dag.py
[2022-11-24 11:58:06,166] {processor.py:161} INFO - Processing /opt/airflow/dags/second_dag.py took 0.073 seconds
[2022-11-24 11:58:36,651] {processor.py:153} INFO - Started process (PID=362) to work on /opt/airflow/dags/second_dag.py
[2022-11-24 11:58:36,654] {processor.py:641} INFO - Processing file /opt/airflow/dags/second_dag.py for tasks to queue
[2022-11-24 11:58:36,656] {logging_mixin.py:115} INFO - [2022-11-24 11:58:36,656] {dagbag.py:507} INFO - Filling up the DagBag from /opt/airflow/dags/second_dag.py
[2022-11-24 11:58:36,724] {logging_mixin.py:115} INFO - [2022-11-24 11:58:36,719] {dagbag.py:320} ERROR - Failed to import: /opt/airflow/dags/second_dag.py
Traceback (most recent call last):
  File "/home/airflow/.local/lib/python3.7/site-packages/airflow/models/dagbag.py", line 317, in parse
    loader.exec_module(new_module)
  File "<frozen importlib._bootstrap_external>", line 728, in exec_module
  File "<frozen importlib._bootstrap>", line 219, in _call_with_frames_removed
  File "/opt/airflow/dags/second_dag.py", line 24, in <module>
    sshHook = SSHHook('ec2_ssh_connection')
  File "/home/airflow/.local/lib/python3.7/site-packages/airflow/providers/ssh/hooks/ssh.py", line 142, in __init__
    conn = self.get_connection(self.ssh_conn_id)
  File "/home/airflow/.local/lib/python3.7/site-packages/airflow/hooks/base.py", line 67, in get_connection
    conn = Connection.get_connection_from_secrets(conn_id)
  File "/home/airflow/.local/lib/python3.7/site-packages/airflow/models/connection.py", line 430, in get_connection_from_secrets
    raise AirflowNotFoundException(f"The conn_id `{conn_id}` isn't defined")
airflow.exceptions.AirflowNotFoundException: The conn_id `ec2_ssh_connection` isn't defined
[2022-11-24 11:58:36,726] {processor.py:653} WARNING - No viable dags retrieved from /opt/airflow/dags/second_dag.py
[2022-11-24 11:58:36,734] {processor.py:161} INFO - Processing /opt/airflow/dags/second_dag.py took 0.088 seconds
[2022-11-24 11:59:07,037] {processor.py:153} INFO - Started process (PID=427) to work on /opt/airflow/dags/second_dag.py
[2022-11-24 11:59:07,040] {processor.py:641} INFO - Processing file /opt/airflow/dags/second_dag.py for tasks to queue
[2022-11-24 11:59:07,041] {logging_mixin.py:115} INFO - [2022-11-24 11:59:07,041] {dagbag.py:507} INFO - Filling up the DagBag from /opt/airflow/dags/second_dag.py
[2022-11-24 11:59:07,088] {logging_mixin.py:115} INFO - [2022-11-24 11:59:07,084] {dagbag.py:320} ERROR - Failed to import: /opt/airflow/dags/second_dag.py
Traceback (most recent call last):
  File "/home/airflow/.local/lib/python3.7/site-packages/airflow/models/dagbag.py", line 317, in parse
    loader.exec_module(new_module)
  File "<frozen importlib._bootstrap_external>", line 728, in exec_module
  File "<frozen importlib._bootstrap>", line 219, in _call_with_frames_removed
  File "/opt/airflow/dags/second_dag.py", line 24, in <module>
    sshHook = SSHHook('ec2_ssh_connection')
  File "/home/airflow/.local/lib/python3.7/site-packages/airflow/providers/ssh/hooks/ssh.py", line 142, in __init__
    conn = self.get_connection(self.ssh_conn_id)
  File "/home/airflow/.local/lib/python3.7/site-packages/airflow/hooks/base.py", line 67, in get_connection
    conn = Connection.get_connection_from_secrets(conn_id)
  File "/home/airflow/.local/lib/python3.7/site-packages/airflow/models/connection.py", line 430, in get_connection_from_secrets
    raise AirflowNotFoundException(f"The conn_id `{conn_id}` isn't defined")
airflow.exceptions.AirflowNotFoundException: The conn_id `ec2_ssh_connection` isn't defined
[2022-11-24 11:59:07,090] {processor.py:653} WARNING - No viable dags retrieved from /opt/airflow/dags/second_dag.py
[2022-11-24 11:59:07,098] {processor.py:161} INFO - Processing /opt/airflow/dags/second_dag.py took 0.064 seconds
[2022-11-24 11:59:38,153] {processor.py:153} INFO - Started process (PID=484) to work on /opt/airflow/dags/second_dag.py
[2022-11-24 11:59:38,155] {processor.py:641} INFO - Processing file /opt/airflow/dags/second_dag.py for tasks to queue
[2022-11-24 11:59:38,157] {logging_mixin.py:115} INFO - [2022-11-24 11:59:38,156] {dagbag.py:507} INFO - Filling up the DagBag from /opt/airflow/dags/second_dag.py
[2022-11-24 11:59:38,230] {logging_mixin.py:115} INFO - [2022-11-24 11:59:38,225] {dagbag.py:320} ERROR - Failed to import: /opt/airflow/dags/second_dag.py
Traceback (most recent call last):
  File "/home/airflow/.local/lib/python3.7/site-packages/airflow/models/dagbag.py", line 317, in parse
    loader.exec_module(new_module)
  File "<frozen importlib._bootstrap_external>", line 728, in exec_module
  File "<frozen importlib._bootstrap>", line 219, in _call_with_frames_removed
  File "/opt/airflow/dags/second_dag.py", line 24, in <module>
    sshHook = SSHHook('ec2_ssh_connection')
  File "/home/airflow/.local/lib/python3.7/site-packages/airflow/providers/ssh/hooks/ssh.py", line 142, in __init__
    conn = self.get_connection(self.ssh_conn_id)
  File "/home/airflow/.local/lib/python3.7/site-packages/airflow/hooks/base.py", line 67, in get_connection
    conn = Connection.get_connection_from_secrets(conn_id)
  File "/home/airflow/.local/lib/python3.7/site-packages/airflow/models/connection.py", line 430, in get_connection_from_secrets
    raise AirflowNotFoundException(f"The conn_id `{conn_id}` isn't defined")
airflow.exceptions.AirflowNotFoundException: The conn_id `ec2_ssh_connection` isn't defined
[2022-11-24 11:59:38,231] {processor.py:653} WARNING - No viable dags retrieved from /opt/airflow/dags/second_dag.py
[2022-11-24 11:59:38,254] {processor.py:161} INFO - Processing /opt/airflow/dags/second_dag.py took 0.106 seconds
[2022-11-24 12:00:08,556] {processor.py:153} INFO - Started process (PID=549) to work on /opt/airflow/dags/second_dag.py
[2022-11-24 12:00:08,558] {processor.py:641} INFO - Processing file /opt/airflow/dags/second_dag.py for tasks to queue
[2022-11-24 12:00:08,560] {logging_mixin.py:115} INFO - [2022-11-24 12:00:08,560] {dagbag.py:507} INFO - Filling up the DagBag from /opt/airflow/dags/second_dag.py
[2022-11-24 12:00:08,625] {logging_mixin.py:115} INFO - [2022-11-24 12:00:08,621] {dagbag.py:320} ERROR - Failed to import: /opt/airflow/dags/second_dag.py
Traceback (most recent call last):
  File "/home/airflow/.local/lib/python3.7/site-packages/airflow/models/dagbag.py", line 317, in parse
    loader.exec_module(new_module)
  File "<frozen importlib._bootstrap_external>", line 728, in exec_module
  File "<frozen importlib._bootstrap>", line 219, in _call_with_frames_removed
  File "/opt/airflow/dags/second_dag.py", line 24, in <module>
    sshHook = SSHHook('ec2_ssh_connection')
  File "/home/airflow/.local/lib/python3.7/site-packages/airflow/providers/ssh/hooks/ssh.py", line 142, in __init__
    conn = self.get_connection(self.ssh_conn_id)
  File "/home/airflow/.local/lib/python3.7/site-packages/airflow/hooks/base.py", line 67, in get_connection
    conn = Connection.get_connection_from_secrets(conn_id)
  File "/home/airflow/.local/lib/python3.7/site-packages/airflow/models/connection.py", line 430, in get_connection_from_secrets
    raise AirflowNotFoundException(f"The conn_id `{conn_id}` isn't defined")
airflow.exceptions.AirflowNotFoundException: The conn_id `ec2_ssh_connection` isn't defined
[2022-11-24 12:00:08,630] {processor.py:653} WARNING - No viable dags retrieved from /opt/airflow/dags/second_dag.py
[2022-11-24 12:00:08,638] {processor.py:161} INFO - Processing /opt/airflow/dags/second_dag.py took 0.087 seconds
[2022-11-24 12:00:42,706] {processor.py:153} INFO - Started process (PID=615) to work on /opt/airflow/dags/second_dag.py
[2022-11-24 12:00:42,708] {processor.py:641} INFO - Processing file /opt/airflow/dags/second_dag.py for tasks to queue
[2022-11-24 12:00:42,709] {logging_mixin.py:115} INFO - [2022-11-24 12:00:42,709] {dagbag.py:507} INFO - Filling up the DagBag from /opt/airflow/dags/second_dag.py
[2022-11-24 12:00:42,748] {logging_mixin.py:115} INFO - [2022-11-24 12:00:42,746] {dagbag.py:320} ERROR - Failed to import: /opt/airflow/dags/second_dag.py
Traceback (most recent call last):
  File "/home/airflow/.local/lib/python3.7/site-packages/airflow/models/dagbag.py", line 317, in parse
    loader.exec_module(new_module)
  File "<frozen importlib._bootstrap_external>", line 728, in exec_module
  File "<frozen importlib._bootstrap>", line 219, in _call_with_frames_removed
  File "/opt/airflow/dags/second_dag.py", line 24, in <module>
    sshHook = SSHHook('ec2_ssh_connection')
  File "/home/airflow/.local/lib/python3.7/site-packages/airflow/providers/ssh/hooks/ssh.py", line 142, in __init__
    conn = self.get_connection(self.ssh_conn_id)
  File "/home/airflow/.local/lib/python3.7/site-packages/airflow/hooks/base.py", line 67, in get_connection
    conn = Connection.get_connection_from_secrets(conn_id)
  File "/home/airflow/.local/lib/python3.7/site-packages/airflow/models/connection.py", line 430, in get_connection_from_secrets
    raise AirflowNotFoundException(f"The conn_id `{conn_id}` isn't defined")
airflow.exceptions.AirflowNotFoundException: The conn_id `ec2_ssh_connection` isn't defined
[2022-11-24 12:00:42,749] {processor.py:653} WARNING - No viable dags retrieved from /opt/airflow/dags/second_dag.py
[2022-11-24 12:00:42,756] {processor.py:161} INFO - Processing /opt/airflow/dags/second_dag.py took 0.053 seconds
[2022-11-24 12:01:15,556] {processor.py:153} INFO - Started process (PID=680) to work on /opt/airflow/dags/second_dag.py
[2022-11-24 12:01:15,557] {processor.py:641} INFO - Processing file /opt/airflow/dags/second_dag.py for tasks to queue
[2022-11-24 12:01:15,558] {logging_mixin.py:115} INFO - [2022-11-24 12:01:15,558] {dagbag.py:507} INFO - Filling up the DagBag from /opt/airflow/dags/second_dag.py
[2022-11-24 12:01:15,675] {logging_mixin.py:115} INFO - [2022-11-24 12:01:15,672] {dagbag.py:320} ERROR - Failed to import: /opt/airflow/dags/second_dag.py
Traceback (most recent call last):
  File "/home/airflow/.local/lib/python3.7/site-packages/airflow/models/dagbag.py", line 317, in parse
    loader.exec_module(new_module)
  File "<frozen importlib._bootstrap_external>", line 728, in exec_module
  File "<frozen importlib._bootstrap>", line 219, in _call_with_frames_removed
  File "/opt/airflow/dags/second_dag.py", line 24, in <module>
    sshHook = SSHHook('ec2_ssh_connection')
  File "/home/airflow/.local/lib/python3.7/site-packages/airflow/providers/ssh/hooks/ssh.py", line 142, in __init__
    conn = self.get_connection(self.ssh_conn_id)
  File "/home/airflow/.local/lib/python3.7/site-packages/airflow/hooks/base.py", line 67, in get_connection
    conn = Connection.get_connection_from_secrets(conn_id)
  File "/home/airflow/.local/lib/python3.7/site-packages/airflow/models/connection.py", line 430, in get_connection_from_secrets
    raise AirflowNotFoundException(f"The conn_id `{conn_id}` isn't defined")
airflow.exceptions.AirflowNotFoundException: The conn_id `ec2_ssh_connection` isn't defined
[2022-11-24 12:01:15,676] {processor.py:653} WARNING - No viable dags retrieved from /opt/airflow/dags/second_dag.py
[2022-11-24 12:01:15,683] {processor.py:161} INFO - Processing /opt/airflow/dags/second_dag.py took 0.130 seconds
[2022-11-24 12:01:46,545] {processor.py:153} INFO - Started process (PID=743) to work on /opt/airflow/dags/second_dag.py
[2022-11-24 12:01:46,547] {processor.py:641} INFO - Processing file /opt/airflow/dags/second_dag.py for tasks to queue
[2022-11-24 12:01:46,549] {logging_mixin.py:115} INFO - [2022-11-24 12:01:46,549] {dagbag.py:507} INFO - Filling up the DagBag from /opt/airflow/dags/second_dag.py
[2022-11-24 12:01:46,711] {logging_mixin.py:115} INFO - [2022-11-24 12:01:46,709] {dagbag.py:320} ERROR - Failed to import: /opt/airflow/dags/second_dag.py
Traceback (most recent call last):
  File "/home/airflow/.local/lib/python3.7/site-packages/airflow/models/dagbag.py", line 317, in parse
    loader.exec_module(new_module)
  File "<frozen importlib._bootstrap_external>", line 728, in exec_module
  File "<frozen importlib._bootstrap>", line 219, in _call_with_frames_removed
  File "/opt/airflow/dags/second_dag.py", line 24, in <module>
    sshHook = SSHHook('ec2_ssh_connection')
  File "/home/airflow/.local/lib/python3.7/site-packages/airflow/providers/ssh/hooks/ssh.py", line 142, in __init__
    conn = self.get_connection(self.ssh_conn_id)
  File "/home/airflow/.local/lib/python3.7/site-packages/airflow/hooks/base.py", line 67, in get_connection
    conn = Connection.get_connection_from_secrets(conn_id)
  File "/home/airflow/.local/lib/python3.7/site-packages/airflow/models/connection.py", line 430, in get_connection_from_secrets
    raise AirflowNotFoundException(f"The conn_id `{conn_id}` isn't defined")
airflow.exceptions.AirflowNotFoundException: The conn_id `ec2_ssh_connection` isn't defined
[2022-11-24 12:01:46,716] {processor.py:653} WARNING - No viable dags retrieved from /opt/airflow/dags/second_dag.py
[2022-11-24 12:01:46,724] {processor.py:161} INFO - Processing /opt/airflow/dags/second_dag.py took 0.182 seconds
[2022-11-24 12:02:17,575] {processor.py:153} INFO - Started process (PID=808) to work on /opt/airflow/dags/second_dag.py
[2022-11-24 12:02:17,580] {processor.py:641} INFO - Processing file /opt/airflow/dags/second_dag.py for tasks to queue
[2022-11-24 12:02:17,582] {logging_mixin.py:115} INFO - [2022-11-24 12:02:17,582] {dagbag.py:507} INFO - Filling up the DagBag from /opt/airflow/dags/second_dag.py
[2022-11-24 12:02:17,747] {logging_mixin.py:115} INFO - [2022-11-24 12:02:17,744] {dagbag.py:320} ERROR - Failed to import: /opt/airflow/dags/second_dag.py
Traceback (most recent call last):
  File "/home/airflow/.local/lib/python3.7/site-packages/airflow/models/dagbag.py", line 317, in parse
    loader.exec_module(new_module)
  File "<frozen importlib._bootstrap_external>", line 728, in exec_module
  File "<frozen importlib._bootstrap>", line 219, in _call_with_frames_removed
  File "/opt/airflow/dags/second_dag.py", line 24, in <module>
    sshHook = SSHHook('ec2_ssh_connection')
  File "/home/airflow/.local/lib/python3.7/site-packages/airflow/providers/ssh/hooks/ssh.py", line 142, in __init__
    conn = self.get_connection(self.ssh_conn_id)
  File "/home/airflow/.local/lib/python3.7/site-packages/airflow/hooks/base.py", line 67, in get_connection
    conn = Connection.get_connection_from_secrets(conn_id)
  File "/home/airflow/.local/lib/python3.7/site-packages/airflow/models/connection.py", line 430, in get_connection_from_secrets
    raise AirflowNotFoundException(f"The conn_id `{conn_id}` isn't defined")
airflow.exceptions.AirflowNotFoundException: The conn_id `ec2_ssh_connection` isn't defined
[2022-11-24 12:02:17,749] {processor.py:653} WARNING - No viable dags retrieved from /opt/airflow/dags/second_dag.py
[2022-11-24 12:02:17,757] {processor.py:161} INFO - Processing /opt/airflow/dags/second_dag.py took 0.188 seconds
[2022-11-24 12:02:47,975] {processor.py:153} INFO - Started process (PID=875) to work on /opt/airflow/dags/second_dag.py
[2022-11-24 12:02:47,977] {processor.py:641} INFO - Processing file /opt/airflow/dags/second_dag.py for tasks to queue
[2022-11-24 12:02:47,979] {logging_mixin.py:115} INFO - [2022-11-24 12:02:47,978] {dagbag.py:507} INFO - Filling up the DagBag from /opt/airflow/dags/second_dag.py
[2022-11-24 12:02:48,149] {logging_mixin.py:115} INFO - [2022-11-24 12:02:48,146] {dagbag.py:320} ERROR - Failed to import: /opt/airflow/dags/second_dag.py
Traceback (most recent call last):
  File "/home/airflow/.local/lib/python3.7/site-packages/airflow/models/dagbag.py", line 317, in parse
    loader.exec_module(new_module)
  File "<frozen importlib._bootstrap_external>", line 728, in exec_module
  File "<frozen importlib._bootstrap>", line 219, in _call_with_frames_removed
  File "/opt/airflow/dags/second_dag.py", line 24, in <module>
    sshHook = SSHHook('ec2_ssh_connection')
  File "/home/airflow/.local/lib/python3.7/site-packages/airflow/providers/ssh/hooks/ssh.py", line 142, in __init__
    conn = self.get_connection(self.ssh_conn_id)
  File "/home/airflow/.local/lib/python3.7/site-packages/airflow/hooks/base.py", line 67, in get_connection
    conn = Connection.get_connection_from_secrets(conn_id)
  File "/home/airflow/.local/lib/python3.7/site-packages/airflow/models/connection.py", line 430, in get_connection_from_secrets
    raise AirflowNotFoundException(f"The conn_id `{conn_id}` isn't defined")
airflow.exceptions.AirflowNotFoundException: The conn_id `ec2_ssh_connection` isn't defined
[2022-11-24 12:02:48,157] {processor.py:653} WARNING - No viable dags retrieved from /opt/airflow/dags/second_dag.py
[2022-11-24 12:02:48,168] {processor.py:161} INFO - Processing /opt/airflow/dags/second_dag.py took 0.197 seconds
[2022-11-24 12:03:18,759] {processor.py:153} INFO - Started process (PID=942) to work on /opt/airflow/dags/second_dag.py
[2022-11-24 12:03:18,762] {processor.py:641} INFO - Processing file /opt/airflow/dags/second_dag.py for tasks to queue
[2022-11-24 12:03:18,764] {logging_mixin.py:115} INFO - [2022-11-24 12:03:18,764] {dagbag.py:507} INFO - Filling up the DagBag from /opt/airflow/dags/second_dag.py
[2022-11-24 12:03:18,893] {logging_mixin.py:115} INFO - [2022-11-24 12:03:18,891] {dagbag.py:320} ERROR - Failed to import: /opt/airflow/dags/second_dag.py
Traceback (most recent call last):
  File "/home/airflow/.local/lib/python3.7/site-packages/airflow/models/dagbag.py", line 317, in parse
    loader.exec_module(new_module)
  File "<frozen importlib._bootstrap_external>", line 728, in exec_module
  File "<frozen importlib._bootstrap>", line 219, in _call_with_frames_removed
  File "/opt/airflow/dags/second_dag.py", line 24, in <module>
    sshHook = SSHHook('ec2_ssh_connection')
  File "/home/airflow/.local/lib/python3.7/site-packages/airflow/providers/ssh/hooks/ssh.py", line 142, in __init__
    conn = self.get_connection(self.ssh_conn_id)
  File "/home/airflow/.local/lib/python3.7/site-packages/airflow/hooks/base.py", line 67, in get_connection
    conn = Connection.get_connection_from_secrets(conn_id)
  File "/home/airflow/.local/lib/python3.7/site-packages/airflow/models/connection.py", line 430, in get_connection_from_secrets
    raise AirflowNotFoundException(f"The conn_id `{conn_id}` isn't defined")
airflow.exceptions.AirflowNotFoundException: The conn_id `ec2_ssh_connection` isn't defined
[2022-11-24 12:03:18,895] {processor.py:653} WARNING - No viable dags retrieved from /opt/airflow/dags/second_dag.py
[2022-11-24 12:03:18,902] {processor.py:161} INFO - Processing /opt/airflow/dags/second_dag.py took 0.146 seconds
[2022-11-24 12:03:49,813] {processor.py:153} INFO - Started process (PID=1009) to work on /opt/airflow/dags/second_dag.py
[2022-11-24 12:03:49,814] {processor.py:641} INFO - Processing file /opt/airflow/dags/second_dag.py for tasks to queue
[2022-11-24 12:03:49,816] {logging_mixin.py:115} INFO - [2022-11-24 12:03:49,816] {dagbag.py:507} INFO - Filling up the DagBag from /opt/airflow/dags/second_dag.py
[2022-11-24 12:03:49,953] {logging_mixin.py:115} INFO - [2022-11-24 12:03:49,951] {dagbag.py:320} ERROR - Failed to import: /opt/airflow/dags/second_dag.py
Traceback (most recent call last):
  File "/home/airflow/.local/lib/python3.7/site-packages/airflow/models/dagbag.py", line 317, in parse
    loader.exec_module(new_module)
  File "<frozen importlib._bootstrap_external>", line 728, in exec_module
  File "<frozen importlib._bootstrap>", line 219, in _call_with_frames_removed
  File "/opt/airflow/dags/second_dag.py", line 24, in <module>
    sshHook = SSHHook('ec2_ssh_connection')
  File "/home/airflow/.local/lib/python3.7/site-packages/airflow/providers/ssh/hooks/ssh.py", line 142, in __init__
    conn = self.get_connection(self.ssh_conn_id)
  File "/home/airflow/.local/lib/python3.7/site-packages/airflow/hooks/base.py", line 67, in get_connection
    conn = Connection.get_connection_from_secrets(conn_id)
  File "/home/airflow/.local/lib/python3.7/site-packages/airflow/models/connection.py", line 430, in get_connection_from_secrets
    raise AirflowNotFoundException(f"The conn_id `{conn_id}` isn't defined")
airflow.exceptions.AirflowNotFoundException: The conn_id `ec2_ssh_connection` isn't defined
[2022-11-24 12:03:49,956] {processor.py:653} WARNING - No viable dags retrieved from /opt/airflow/dags/second_dag.py
[2022-11-24 12:03:49,963] {processor.py:161} INFO - Processing /opt/airflow/dags/second_dag.py took 0.155 seconds
